监控系统存在的意义如何及时发现问题、如何快速定位问题

为什么要搞自建监控？

* 方便团队做自定义的UV用户识别，比如通过登录账号ID或者通过设备信息；甚至从设备信息转入登录态后的继承
* 方便接入自己团队的各种告警业务等
* 方便做各维度数据的联合分析，比如发生错误可以联动查询用户行为追溯数据等
* 方便做业务需求上的拓展，比如自定义埋点、特殊的数据分析维度
* 方便前后端全链路的一个API请求链路分析
[原文链接](https://juejin.cn/post/7172072612430872584)
# 性能监控

性能监控内容省略在【浏览器渲染和性能优化文章中】
# 行为监控

[原文链接](https://juejin.cn/post/7098656658649251877)

* PV、UV量，日同比、周同比等。能清晰的明白流量变化。
* 用户热点页面、高访问量TOP10
* 设备、浏览器语言、浏览器、活跃时间段等的用户特征
* 用户的行为追踪：某个用户，进入了网站后的一系列操作或者跳转行为；
* 用户自定义埋点上报用户行为：想做一些自定义事件的监听，比如播放某个视频的行为动作。
* 多语种站点，每个语种的用户量

需要追踪的事件包括以下：

* 路由跳转行为
* 点击行为
* ajax 请求行为
* 用户自定义事件

* 用户的基本信息
* 用户行为记录栈
* 路由跳转
* PV、UV
* 点击事件
* 用户自定义埋点
* HTTP 请求捕获
* XMLHttpRequest 的劫持
* Fetch 的劫持
* 简单初始化封装
* 页面停留时间
* 访客来路
* 用户来路地址
* 用户来路方式
* 代码封装

# 错误监控

[原文链接](https://juejin.cn/post/7100841779854835719/)

众所周知，无论进行发布前的单元测试、集成测试、人工测试进行再多轮，都会难免漏掉一些边缘的测试场景，甚至还有一些奇奇怪怪的玄学故障出现；而出现报错后，轻则某些数据页面无法访问，重则导致客户数据出错；
这时，一个完善的错误监控体系就派上很大的用场，它可以帮助我们做以下的事情：

* 应用报错时，及时知晓线上应用出现了错误，及时安排修复止损；
* 应用报错后，根据上报的用户行为追踪记录数据，迅速进行bug复现；
* 应用报错后，通过上报的错误行列以及错误信息，找到报错源码并快速修正；
* 数据采集后，进行分析提供宏观的 错误数、错误率、影响用户数等关键指标；

## 错误监控的要点

### 生成错误 uid
首先，什么叫为每个错误生成 uid，这里生成的 uid 有什么用呢？答案其实很简单：

一次用户访问（页签未关闭），上报过一次错误后，后续产生重复错误不再上报,多个用户产生的同一个错误，在服务端可以归类，分析影响用户数、错误数等指标,需要注意的是，对于同一个原因产生的同一个错误，生成的 uid 是相同的。

```
// 对每一个错误详情，生成一串编码
// unescape将任何转译字符编译成十六进制
// window.btoa 将二进制字符编译成base64编码
export const getErrorUid = (input: string) => {
  return window.btoa(unescape(encodeURIComponent(input)));
};
```
### 错误堆栈
Error对象 里的 Stack错误堆栈，里面包含了很多信息：包括调用链、文件名、调用地址行列信息。

```
// 正则表达式，用以解析堆栈split后得到的字符串
const FULL_MATCH =
  /^\s*at (?:(.*?) ?\()?((?:file|https?|blob|chrome-extension|address|native|eval|webpack|<anonymous>|[-a-z]+:|.*bundle|\/).*?)(?::(\d+))?(?::(\d+))?\)?\s*$/i;

// 限制只追溯10个
const STACKTRACE_LIMIT = 10;

// 解析每一行
export function parseStackLine(line: string) {
  const lineMatch = line.match(FULL_MATCH);
  if (!lineMatch) return {};
  const filename = lineMatch[2];
  const functionName = lineMatch[1] || '';
  const lineno = parseInt(lineMatch[3], 10) || undefined;
  const colno = parseInt(lineMatch[4], 10) || undefined;
  return {
    filename,
    functionName,
    lineno,
    colno,
  };
}

// 解析错误堆栈
export function parseStackFrames(error: Error) {
  const { stack } = error;
  // 无 stack 时直接返回
  if (!stack) return [];
  const frames = [];
  for (const line of stack.split('\n').slice(1)) {
    const frame = parseStackLine(line);
    if (frame) {
      frames.push(frame);
    }
  }
  return frames.slice(0, STACKTRACE_LIMIT);
}
```


# JS的几种错误类型

## 基类 Error
Error是基类型,其他内置错误类型都是继承该类型,因此所有内置错误类型都是共享相同的属性(所有错误对象上的方法都是这个默认类型定义的方法)。浏览器很少会抛出Error类型的错误,该类型主要用于抛出自定义错误。

```
new Error([message[, fileName[,lineNumber]]])

message 可选。人类可阅读的错误描述信息。
fileName 可选。被创建的Error对象的fileName属性值。默认是调用Error构造器代码所在的文件 的名字。
lineNumber 可选。被创建的Error对象的lineNumber属性值。默认是调用Error构造器代码所在的文件的行号。
当像函数一样使用 Error 时 -- 如果没有 new，它将返回一个 Error 对象。所以， 仅仅调用 Error 产生的结果与通过new 关键字构造 Error 对象生成的结果相同。 

// this:
const x = Error('I was created using a function call!');
// has the same functionality as this:
const y = new Error('I was constructed via the "new" keyword!');
```
Error实例上有哪些属性
```
Error.prototype 可以添加自定义属性和方法
Error.prototype.columnNumber 引发此错误的文件行中的列号
Error.prototype.fileName 引发此错误的文件的路径
Error.prototype.lineNumber 抛出错误的代码在其源文件中所在的行号
Error.prototype.message 错误描述 在实例化的时候可以被重写
Error.prototype.name 表示error类型的名称 初始值为Error
Error.prototype.stack 错误堆栈
```
## ReferenceError（引用错误）
表示引用错误，使用了未声明的变量。错误之前的代码会执行，之后代码不会执行

```
1.console.log(aaaa) //使用一个没有定义的变量
2.Math.random()=1 //把变量赋值给一个无法赋值的xx
```
捕获一个错误

```
try {
  var a = undefinedVariable;
} catch (e) {
  console.log(e instanceof ReferenceError); // true
  console.log(e.message);                   // "undefinedVariable is not defined"
  console.log(e.name);                      // "ReferenceError"
  console.log(e.fileName);                  // "Scratchpad/1"
  console.log(e.lineNumber);                // 2
  console.log(e.columnNumber);              // 6
  console.log(e.stack);                     // "@Scratchpad/2:2:7\n"
}
```
新建错误

```
try {
  throw new ReferenceError('Hello', 'aaa.js', 10);
} catch (e) {
  console.log(e instanceof ReferenceError); // true
  console.log(e.message);                   // "Hello"
  console.log(e.name);                      // "ReferenceError"
  console.log(e.fileName);                  // "aaa.js"
  console.log(e.lineNumber);                // 10
  console.log(e.columnNumber);              // 0
  console.log(e.stack);                     // "@Scratchpad/2:2:9\n"
}
```

## RangeError

```
var arr=new Array(-1)
//Uncaught RangeError: Invalid array length at <anonymous>:1:11
function a(number){
    if(number>0){
        return a(number)
    }
}
a(100) //Maximum call stack size exceeded
var a=new Array(Number.MAX_SAFE_INTEGER)
```
## TypeError
TypeError在JavaScript中很常见,主要发生变量在运行时的访问不是预期类型,或者访问不存在的方法时,尤其是在使用类型特定的操作而变量类型不对时。在给函数传参前没有验证的情况下,错误发生较多。比如a变量是个基本类型，却被当做函数调用
```

//Uncaught TypeError: a is not a function at <anonymous>:3:1
1.var a=100 a() 
2.var a={} a.foo()
```
## SyntaxError
当我们输入 JS 引擎不能理解的代码时，就会发生这个错误。JS引擎在解析期间会捕获了这个错误，而不是运行时。或者给eval()传入的字符串包含JavaScript语法错误时，也会抛出此异常

```
//Uncaught SyntaxError: Unexpected number
1.var aaa=function(){
    var p 1=199
}
aaa()
2.eval('hoo bar')
```
## URIError

```
URIError只会在使用encodeURL()或decodeURL()时，传入了格式错误的URL时发生,但非常罕见,因为上面两个函数非常稳健.
比如对空格进行编码，然后把编码的结果改为非法的结果，对该结果再进行解码，就会抛出异常

encodeURI(' ') '%20' decodeURI('%')
```

## EvalError
会在使用eval()函数发生异常时抛出。

# try catch 配合 await 捕获 Promise错误

# 无法捕获到的错误

## 无法捕获到的异步错误
```
new Promise(() => {
  setTimeout(() => {
    throw new Error('err') // uncaught
  }, 0)
}).catch((e) => {
  console.log(e)
})

这个情况要用 reject 方式抛出异常才能被捕获：

new Promise((res, rej) => {
  setTimeout(() => {
    rej('err') // caught
  }, 0)
}).catch((e) => {
  console.log(e)
})
```
```
另一种情况是，这个 await 没有被执行到：

const wait = (ms) => new Promise((res) => setTimeout(res, ms))

;(async () => {
  try {
    const p1 = wait(3000).then(() => {
      throw new Error('err')
    }) // uncaught
    await wait(2000).then(() => {
      throw new Error('err2')
    }) // caught
    await p1
  } catch (e) {
    console.log(e)
  }
})()

```
p1 等待 3s 后抛出异常，但因为 2s 后抛出了 err2 异常，中断了代码执行，所以 await p1 不会被执行到，导致这个异常不会被 catch 住。 而且有意思的是，如果换一个场景，提前执行了 p1，等 1s 后再 await p1，那异常就从无法捕获变成可以捕获了，这样浏览器会怎么处理？

```
const wait = (ms) => new Promise((res) => setTimeout(res, ms))

;(async () => {
  try {
    const p1 = wait(1000).then(() => {
      throw new Error('err')
    })
    await wait(2000)
    await p1
  } catch (e) {
    console.log(e)
  }
})()
```
结论是浏览器 1s 后会抛出一个未捕获异常，但再过 1s 这个未捕获异常就消失了，变成了捕获的异常。
这个行为很奇怪，当程序复杂时很难排查，因为并行的 Promise 建议用 Promise.all 处理：
```
await Promise.all([
  wait(1000).then(() => {
    throw new Error('err')
  }), // p1
  wait(2000),
])
```
另外 Promise 的错误会随着 Promise 链传递，因此建议把 Promise 内多次异步行为改写为多条链的模式，在最后 catch 住错误。
还是之前的例子，Promise 无法捕获内部的异步错误：
```
new Promise((res, rej) => {
  setTimeout(() => {
    throw Error('err')
  }, 1000) // 1
}).catch((error) => {
  console.log(error)
})
但如果写成 Promise Chain，就可以捕获了：
new Promise((res, rej) => {
  setTimeout(res, 1000) // 1
})
  .then((res, rej) => {
    throw Error('err')
  })
  .catch((error) => {
    console.log(error)
  })
```
原因是，用 Promise Chain 代替了内部多次异步嵌套，这样多个异步行为会被拆解为对应 Promise Chain 的同步行为，Promise 就可以捕获啦。

## DOM 事件监听内抛出的错误都无法被捕获

```
document.querySelector('button').addEventListener('click', async () => {
  throw new Error('err') // uncaught
})
同步也一样：
document.querySelector('button').addEventListener('click', () => {
  throw new Error('err') // uncaught
})
```
只能通过函数体内 try catch 来捕获。

## window.addEventListener('error') 

## window.addEventListener('unhandledrejection') 

可以监听所有同步、异步的运行时错误，但无法监听语法、接口、资源加载错误。
而 unhandledrejection 可以监听到 Promise 中抛出的，未被 .catch 捕获的错误。 

## React 的 Error Boundaries

## Vue 的 error handler

## 跨域js错误

a. 给script标签添加crossorigin属性，并且设置anonymous为正确的origin域名或者*，如果不是，则不加载js，还有use-credentials属性，需要设置access-control-allow-credentials，返回true，此时access-control-allow-origin：domain必须设置具体的域名，不支持通配符*

b. 通过try catch包裹，手动调用window.onerror方法，把信息包裹出去
## 捕获js运行异常

### 方法一

我们可以使用 window.onerror 来捕获全局的 JS 运行异常,window.onerror 是一个全局变量，默认值为null。当有js运行时错误触发时，window会触发error事件，并执行 window.onerror(),借助这个特性，我们对 window.onerror 进行重写就可以捕获到代码中的异常；

```
window.onerror = (msg, url, row, col, error) => {
  const exception = {
    // 上报错误归类
    mechanism: {
      type: 'js'
    },
    // 错误信息
    value: msg,
    // 错误类型
    type: error.name || 'UnKnowun',
    // 解析后的错误堆栈
    stackTrace: {
      frames: parseStackFrames(error),
    },
    meta: {
      url, // 文件地址
      row, // 行号
      col, // 列号
    }
  };
  // 获取了报错详情，就可以走上报方法上报错误信息
  console.log('JS运行error', exception);
  return true; // 返回 true,阻止了默认事件执行,也就是原本将要在控制台打印的错误信息
};
```
### 方法二

我们还可以使用 window.addEventListener('error') 来捕获 JS运行异常；它会比 window.onerror 先触发。

```
// 初始化 JS异常 的数据获取和上报
initJsError = (): void => {
  const handler = (event: ErrorEvent) => {
    // 阻止向上抛出控制台报错
    event.preventDefault();
    // 如果不是 JS异常 就结束
    if (getErrorKey(event) !== mechanismType.JS) return;
    const exception = {
      // 上报错误归类
      mechanism: {
        type: mechanismType.JS,
      },
      // 错误信息
      value: event.message,
      // 错误类型
      type: (event.error && event.error.name) || 'UnKnowun',
      // 解析后的错误堆栈
      stackTrace: {
        frames: parseStackFrames(event.error),
      },
      // 用户行为追踪 breadcrumbs 在 errorSendHandler 中统一封装
      // 页面基本信息 pageInformation 也在 errorSendHandler 中统一封装
      // 错误的标识码
      errorUid: getErrorUid(`${mechanismType.JS}-${event.message}-${event.filename}`),
      // 附带信息
      meta: {
        // file 错误所处的文件地址
        file: event.filename,
        // col 错误列号
        col: event.colno,
        // row 错误行号
        row: event.lineno,
      },
    } as ExceptionMetrics;
    // 一般错误异常立刻上报，不用缓存在本地
    this.errorSendHandler(exception);
  };
  window.addEventListener('error', (event) => handler(event), true);
};
```

### 两者的区别和选用

它们两者均可以捕获到 JS运行异常，但是 addEventListener('error')除了可以监听 **JS运行异常** 之外，还可以同时捕获到 **静态资源加载异常**

onerror 可以接受多个参数。而 addEventListener('error') 只有一个保存所有错误信息的参数

建议使用第二种 addEventListener('error') 的方式；原因很简单：不像方法一可以被 window.onerror 重新覆盖；而且可以同时处理静态资源错误

## JS运行时的错误类型
类型             含义            说明
SyntaxError    语法错误         语法错误 
ReferenceError 引用错误         常见于引用了一个不存在的变量： let a = undefinedVariable
RangeError     有效范围错误      数值变量或参数超出了其有效范围。 
                               常见于 1.创建一个负长度数组 
                               2.Number对象的方法参数超出范围：let b = new Array(-1)

TypeError      类型错误         常见于变量或参数不属于有效类型 
                               let foo = 3;foo();
URIError       URL处理函数错误   使用全局URL处理函数错误，比如 decodeURIComponent('%');

这里有一个点需要特别注意，我们主观感觉上的 SyntaxError 语法错误，除了用 eval() 执行的脚本以外，一般是不可以被捕获到的，比如我们编写一个正常的语法错误：

```
const d d = 1;
// 控制台报错 :Uncaught SyntaxError: Missing initializer in const declaration
// 但是上述的捕获方法无法正常捕获错误；

```
这明显上是一个语法上的错误，但是我们上述的 两个错误捕获方法，都没办法捕获到错误；
只有在代码中通过 eval() 执行的代码脚本才可以正常捕获到错误信息；
```
eval('ddd fff');
// 控制台报错 VM149:1 Uncaught SyntaxError: Unexpected identifier
// 上文的错误捕获方法可以正常捕获到错误；
```
那么，WHY？

其实原因很简单， const d d = 1; 这种语法错误，在编译解析阶段就已经报错了，而拥有语法错误的脚本不会放入任务队列进行执行，自然也就不会有错误冒泡到我们的捕获代码；而我们使用 eval()；在编译解析阶段一切正常，直到执行的时候才进行报错，自然我们就可以捕获到这段错误；

当然，现在代码检查这么好用，早在编写代码时这种语法错误就被避免掉了，一般我们碰不上语法错误的~

## 静态资源加载异常

有的时候，我们界面上的 img图片、CDN资源 突然失效了、打不开了，就比如以下面这个为例子，我们往html中放进一个img，把它的路径设为请求不到的地址：
```
<img src="http://localhost:8888/nottrue.jpg">
// 会报错 GET http://localhost:8888/nottrue.jpg net::ERR_CONNECTION_REFUSED
```
那我们怎么去捕获到这种请求不到资源的、或者说静态资源失效的报错呢？很简单，只需要祭出 window.addEventListener('error') 就可以了。

```
// 静态资源错误的 ErrorTarget
export interface ResourceErrorTarget {
  src?: string;
  tagName?: string;
  outerHTML?: string;
}

// 初始化 静态资源异常 的数据获取和上报
initResourceError = (): void => {
  const handler = (event: Event) => {
    event.preventDefault(); // 阻止向上抛出控制台报错
    // 如果不是跨域脚本异常,就结束
    if (getErrorKey(event) !== mechanismType.RS) return;
    const target = event.target as ResourceErrorTarget;
    const exception = {
      // 上报错误归类
      mechanism: {
        type: mechanismType.RS,
      },
      // 错误信息
      value: '',
      // 错误类型
      type: 'ResourceError',
      // 用户行为追踪 breadcrumbs 在 errorSendHandler 中统一封装
      // 页面基本信息 pageInformation 也在 errorSendHandler 中统一封装
      // 错误的标识码
      errorUid: getErrorUid(`${mechanismType.RS}-${target.src}-${target.tagName}`),
      // 附带信息
      meta: {
        url: target.src,
        html: target.outerHTML,
        type: target.tagName,
      },
    } as ExceptionMetrics;
    // 一般错误异常立刻上报，不用缓存在本地
    this.errorSendHandler(exception);
  };
  window.addEventListener('error', (event) => handler(event), true);
};
```
使用 addEventListener 捕获资源错误时，一定要将 第三个选项设为 true，因为资源错误没有冒泡，所以只能在捕获阶段捕获。同理，由于 window.onerror 是通过在冒泡阶段捕获错误，所以无法捕获资源错误。

## Promise异常
当抛出 Promise异常 时，会触发 unhandledrejection 事件，所以我们只需要去监听它就可以进行 Promise 异常 的捕获了，不过值得注意的一点是：相比与上面所述的直接获取报错的行号、列号等信息，Promise异常 我们只能捕获到一个 报错原因 而已。

```
// 初始化 Promise异常 的数据获取和上报
initPromiseError = (): void => {
  const handler = (event: PromiseRejectionEvent) => {
    event.preventDefault(); // 阻止向上抛出控制台报错
    const value = event.reason.message || event.reason;
    const type = event.reason.name || 'UnKnowun';
    const exception = {
      // 上报错误归类
      mechanism: {
        type: mechanismType.UJ,
      },
      // 错误信息
      value,
      // 错误类型
      type,
      // 解析后的错误堆栈
      stackTrace: {
        frames: parseStackFrames(event.reason),
      },
      // 用户行为追踪 breadcrumbs 在 errorSendHandler 中统一封装
      // 页面基本信息 pageInformation 也在 errorSendHandler 中统一封装
      // 错误的标识码
      errorUid: getErrorUid(`${mechanismType.UJ}-${value}-${type}`),
      // 附带信息
      meta: {},
    } as ExceptionMetrics;
    // 一般错误异常立刻上报，不用缓存在本地
    this.errorSendHandler(exception);
  };

  window.addEventListener('unhandledrejection', (event) => handler(event), true);
};
```
## HTTP请求异常
所谓 Http请求异常 也就是异步请求 HTTP 接口时的异常罢了，比如我调用了一个登录接口，但是我的传参不对，登录接口给我返回了 500 错误码，其实这个时候就已经产生了异常了, 拦截请求错误

xhr拦截和fetch拦截都在发出请求获取response结果的时候，拿到结果上报

## 跨域脚本错误
```
比如说我们新建一个texterror.js 文件到 项目B 的 public 目录下以供外部访问;

// 新建的 texterror.js 文件

const a = new Array(-1);

可以看到，我们在 texterror.js 文件中写了一行会报错的代码，认真看过上文的同学应该知道，它会被捕获在 JS运行异常中，且错误类型为 RangeError ；而我们从 项目A 中引入它；

// 项目B的地址，和项目A端口不同；
<script async src="http://xxxxxx:8081/texterror.js"> </script>

但是我们发现，这里的 msg 信息是 Script error，也没有获取到行号、列号、文件名等的信息，这是怎么回事呢？

其实这是浏览器的一个安全机制：当跨域加载的脚本中发生语法错误时，浏览器出于安全考虑，不会报告错误的细节，而只报告简单的 Script error。浏览器只允许同域下的脚本捕获具体错误信息，而其他脚本只知道发生了一个错误，但无法获知错误的具体内容（控制台仍然可以看到，JS脚本无法捕获），我们上文通过项目A去加载项目B的文件，自然产生了跨域；

```
其实对于三方脚本的错误，我们是否捕获都可以，不过我们需要一点处理，如果不需要捕获的话，就不进行上报，如果需要捕获的话，只上报类型；我们甚至可以只关心自己的远端JS问题，去根据公司域名进行过滤 filename。
我们对上文的 window.addEventListener('error') 再加上对跨域资源的判断，以和正常的代码中错误区分开；

```
// 判断是 JS异常、静态资源异常、还是跨域异常
export const getErrorKey = (event: ErrorEvent | Event) => {
  const isJsError = event instanceof ErrorEvent;
  if (!isJsError) return mechanismType.RS;
  return event.message === 'Script error.' ? mechanismType.CS : mechanismType.JS;
};

// 初始化 跨域异常 的数据获取和上报
initCorsError = (): void => {
  const handler = (event: ErrorEvent) => {
    // 阻止向上抛出控制台报错
    event.preventDefault();
    // 如果不是跨域脚本异常,就结束
    if (getErrorKey(event) !== mechanismType.CS) return;
    const exception = {
      // 上报错误归类
      mechanism: {
        type: mechanismType.CS,
      },
      // 错误信息
      value: event.message,
      // 错误类型
      type: 'CorsError',
      // 错误的标识码
      errorUid: getErrorUid(`${mechanismType.JS}-${event.message}`),
      // 附带信息
      meta: {},
    } as ExceptionMetrics;
    // 自行上报异常，也可以跨域脚本的异常都不上报;
    this.errorSendHandler(exception);
  };
  window.addEventListener('error', (event) => handler(event), true);
};
```
看到了这里，可能还有的同学想了解：那么这种跨域的脚本错误我们就没有办法进行获取错误详情吗？答案还是有的：
我们只需要 开启跨域资源共享CORS（Cross Origin Resource Sharing），就可以捕获错误了~我们需要分两步来进行实现：

添加crossorigin="anonymous"属性。
```
<script src="http://xxxxxxxx/texterror.js" crossorigin="anonymous"></script>

添加跨域HTTP响应头。

Access-Control-Allow-Origin: *

这两步完成后，允许了跨域，我们就可以在错误捕获脚本中获取到具体的错误信息拉！
```
## Vue2、Vue3 错误捕获
[原文链接](https://juejin.cn/post/7143144999515865118)
Vue2 如果在组件渲染时出现运行错误，错误将会被传递至全局 Vue.config.errorHandler 配置函数。

Vue.config.errorHandler = function (err, vm, info) {
    // `info` 是 Vue 特定的错误信息，比如错误所在的生命周期钩子 
    // 只在 2.2.0+ 可用 
}
### render 错误
只需要用这个钩子就可以处理大部分 Vue 应用中的错误（如组件生命周期中的错误、自定义事件处理函数内部错误、v-on DOM 监听器内部抛出的错误），并且回调中自带的 info 参数也标记了这个错误大概是属于哪类，同时它还能处理返回 Promise 链的错误，可以说是非常强大了
```
<template>
  {{ test.obj.xxx }}
</template>
......
created() {
    this.getSomeData()
},
methods: {
    getSomeData() {
      this.fetch().then((res) => {
        this.test = res // 假设这是请求的错误数据
      })
    },
}

Vue.config.errorHandler = function (err, vm, info) {
    console.log('vue异常错误捕获: ', '错误发生在 ' + info)
}
// 上面的错误会报错 info 是 发生在render
```
### Promise错误
```
async created() {
    await this.getSomeData()
},
method: {
    async getSomeData() {
      const res = await this.fetch()
      this.test = res
    },
    fetch() {
      asdasd = 1 // 这里给一个未定义的变量赋值，肯定会报错
      return new Promise((resolve) => {
          // ......省略
      })
    }
// 错误发生在create hook (Promise/async)
```
### click事件
```
<button @click="doSomeThing"> Test </button>
..........
doSomeThing() {
  aaaaaaaa = 111111 // 这里给一个未定义的变量赋值，肯定会报错
},
// 错误发生在 v-on handler
```
Vue3 同 Vue2，如果在组件渲染时出现运行错误，错误将会被传递至全局的 app.config.errorHandler 配置函数。

我们可以利用这两个钩子函数来进行错误捕获，由于是依赖于 Vue配置函数 的错误捕获，所以我们在初始化时，需要用户将 Vue实例 传进来。

### 但是如果错误不发生在vue内部

<button onclick="foo()">bad button</button> 或者

宏任务中的错误也是无法捕获的：
.......
fetch() {
  return new Promise((resolve) => {
    setTimeout(() => {
      asd = 1 // 在宏任务的异步中出现的错误
      resolve({})
    }, 1000)
  })
},

或者

如果 Promise 异常未被正常处理的话，也是捕获不到的，如下代码，注意这里 create 没有用 await 方式调用异步方法：
created() {
    this.getSomeData();
},
methods: {
    async getSomeData() {
      await (asdasd = 1);
    },
},

处理 JS 的额外错误
我们可以用 BOM 提供的全局错误处理函数 window.onerror 来尝试捕获，它接收多个参数：
window.onerror = function (message, source, line, column, error) {
  console.log('全局捕获错误', message, source, line, column, error)
}

处理 Promise 错误
参考 Vue 中 error.js 的代码，同步任务异常捕获就是套上一层 try...catch...，这也解释了为什么 Vue 捕获的错误不会被全局 window.onerror 再次捕获，因为已经在这里抛出了。而异步任务异常处理则是判断如果是 Promise 则把 catch 指向错误处理中。

### 封装一个处理所有错误的plugin
```
function isPromise(ret) {
  return ret && typeof ret.then === 'function' && typeof ret.catch === 'function'
}

const handleMethods = (instance) => {
  if (instance.$options.methods) {
    let actions = instance.$options.methods || {}
    for (const key in actions) {
      if (Object.hasOwnProperty.call(actions, key)) {
        let fn = actions[key]
        actions[key] = function (...args) {
          let ret = args.length > 0 ? fn.apply(this, args) : fn.call(this)
          if (isPromise(ret) && !ret._handled) {
            ret._handled = true
            return ret.catch((e) => errorHandler(e, this, `捕获到了未处理的Promise异常： (Promise/async)`))
          }
        }
      }
    }
  }
}

export default {
  install: (Vue, options) => {
    Vue.mixin({
      beforeCreate() {
        // 由于遍历所有方法可能会造成页面性能损失，所以这里我加了一个条件，需要在路由设置 meta 才能开启该组件下的method额外异常捕获。
        this.$route.meta.capture && handleMethods(this)
      },
    })
  },
}
// 再次处理以下错误，可以被正常捕获，这种方式的好处是我们可以把发生错误的实例信息传进去，如果不想使用这种方法，或是在 Vue3 中使用 setup 方式而不是 options 写法，还可以使用全局的事件监听来捕获。也可以写window.addEventListener('unhandledrejection', (event) => {
  console.log('全局捕获未处理的Promise异常', event)
})来捕获异常。
created() {
    this.getSomeData();
},
methods: {
    async getSomeData() {
      await (asdasd = 1);
    },
},

```
完整代码写一个plugin

```
function errorHandler(err, vm, info) {
  console.log('vue异常错误捕获: ', '错误信息 ' + info)
  // TODO: 处理错误上报
}

const handleMethods = (instance) => {
  if (instance.$options.methods) {
    let actions = instance.$options.methods || {}
    for (const key in actions) {
      if (Object.hasOwnProperty.call(actions, key)) {
        let fn = actions[key]
        actions[key] = function (...args) {
          let ret = args.length > 0 ? fn.apply(this, args) : fn.call(this)
          if (isPromise(ret) && !ret._handled) {
            ret._handled = true
            return ret.catch((e) => errorHandler(e, this, `捕获到了未处理的Promise异常： (Promise/async)`))
          }
        }
      }
    }
  }
}
function isPromise(ret) {
  return ret && typeof ret.then === 'function' && typeof ret.catch === 'function'
}

let GlobalError = {
  install: (Vue, options) => {
    Vue.config.errorHandler = errorHandler
    // eslint-disable-next-line max-params
    window.onerror = function (message, source, line, column, error) {
      errorHandler(message, null, '全局捕获错误')
      // console.log('全局捕获错误', message, source, line, column, error)
    }
    window.addEventListener('unhandledrejection', (event) => {
      errorHandler(event, null, '全局捕获未处理的Promise异常')
    })
    Vue.mixin({
      beforeCreate() {
        this.$route.meta.capture && handleMethods(this)
      },
    })
  },
}

export default GlobalError
```
```
main.js 中引入
import Vue from 'vue'
import App from './App.vue'
import router from './router'

Vue.config.productionTip = false

// 引入错误处理插件
import ErrorPlugin from './errorPlugin'
Vue.use(ErrorPlugin)

new Vue({
  router,
  render: (h) => h(App),
}).$mount('#app')
```
## React 错误捕获
React 一样也有官方提供的错误捕获，和 Vue 不同的是，我们需要自己定义一个高阶组件暴露给项目使用
```
import * as React from 'react';
class ErrorBoundary extends React.Component {
  constructor(props) {
    super(props);
  }
  // ...
  componentDidCatch(error, info) {
    // "组件堆栈" 例子:
    //   in ComponentThatThrows (created by App)
    //   in ErrorBoundary (created by App)
    //   in div (created by App)
    //   in App
  }
  // ...
}
```
项目使用方只需要这样既可：
```
import React from "react";

<ErrorBoundary>
  <Example />
</ErrorBoundary>;

```

# 前端监控平台/监控SDK的架构设计和难点亮点？
[原文链接](https://juejin.cn/post/7108660942686126093)

[架构图](https://p9-juejin.byteimg.com/tos-cn-i-k3u1fbpfcp/789a3cbec5fe4c91a95ca9644d369cf2~tplv-k3u1fbpfcp-zoom-in-crop-mark:4536:0:0:0.awebp?)

我们在应用层SDK上报的数据，在接入层经过 削峰限流 、 数据清洗 和 数据加工 后，将原始日志存储于 ES 中，再经过数据聚合 后，将 issue（聚合的数据） 持久化存储 于 MySQL ，最后提供 RESTful API 提供给监控平台调用。

* 削峰限流是为了避免 激增的大数据量、恶意用户访问等高并发数据导致的服务崩溃；
* 数据加工是为了将 IP、运营商、归属地等各种二次加工数据，封装进上报数据里；
* 数据清洗是为了经由白名单、黑名单过滤等的业务需要，还有避免已关闭的应用数据继续入库；
* 数据聚合是为了将相同信息的数据进行抽象聚合成 issue，以便查询和追踪；

为支持多平台、可拓展、可插拔的特点，整体SDK的架构设计是 内核+插件 的插件式设计；每个 SDK 首先继承于平台无关的 Core 层代码。然后在自身SDK中，初始化内核实例和插件。

# 前端监控项目除了正常的数据采集、数据报表分析以外；会碰上哪些难点可以去突破，或者说可以做出哪些亮点的内容
[原文链接](https://juejin.cn/post/7108660942686126093)
## SDK 如何设计成多平台支持
将每个平台单独放一个仓库，单独维护 ；但是这种办法的问题也很严重：人力资源浪费严重；会导致一些重复的代码很多；维护非常困难；而较好一点的解决方案：我们可以通过插件化对代码进行组织：见下图

我们用 Core 来管理 SDK 内与平台无关的一些代码，比如一些公共方法(生成mid方法、格式化)；
然后每个平台单独一个 SDK；去继承 core 的类；SDK 内自己管理SDK特有的核心方法逻辑，比如上报、参数初始化；
最后就是 Plugins 插件，每个SDK都是由 内核+插件 组成的，我们将所有的插件功能，比如性能监控、错误监控都抽离成插件；

这样子进行 SDK 的设计有很多好处：

每个平台分开打包，每个包的体积会大大缩小；
代码的逻辑更加清晰自恰
最后打包上线时，我们通过修改 build 的脚本，对 packages 文件夹下的每个平台都单独打一个包，并且分开上传到 npm 平台；

## SDK 如何方便的进行业务拓展和定制？

内核里是SDK内的公共逻辑或者基础逻辑。比如数据格式化和数据上报是底下插件都要用到的公共逻辑。而配置初始化是SDK运行的一个基础逻辑；
插件里是SDK的上层拓展业务，比如说监听js错误、监听promise错误，每一个小功能都是一个插件。内核和插件一起组成了 SDK实例 Instance，最后暴露给客户端使用。

我们需要拓展业务，只需要在内核的基础上，不断的往上叠加 Monitor 插件的数量就可以了。

至于说定制化，插件里的功能，都是使用与否不影响整个SDK运行的，所以我们可以自由的让用户对插件里的功能进行定制化，决定哪个监控功能启用、哪个监控功能不启用等等

## SDK 在拓展新业务的时候，如何保证原有业务的正确性

在上述的 内核+插件 设计下，我们开发新业务对原功能的影响基本上可以忽略不计，但是难免有意外，所以在 SDK 项目的层面上，需要有 单元测试 的来保证业务的稳定性。
我们可以引入单元测试，并对 每一个插件，每一个内核方法，都单独编写测试用例，在覆盖率达标的情况下，只要每次代码上传都测试通过，就可以保证原有业务的一个稳定性。

## SDK 如何实现异常隔离以及上报

我们引入监控系统的原因之一就是为了避免页面产生错误，而如果因为监控SDK报错，导致整个应用主业务流程被中断。
最简单粗暴的方法就是把整个 SDK 都用 try catch 包裹起来，那么这样子即使出现了错误，也会被拦截在我们的 catch 里面。

但是我们回过头来想一想，这样简单粗暴的包裹，会带来哪些问题：

* 我们只能获取到一个报错的信息，但是我们无法得知报错的位置、插件；
* 我们没有将其上报，我们无法感知到 SDK 产生了错误
* 我们没法获取 SDK 出错的一个环境数据

那么，我们就需要一个相对优雅的一个异常隔离+上报机制，回想我们上文的架构：内核+插件的形式；我们对每一个插件模块，都单独的用trycatch包裹起来，然后当抛出错误的时候，进行数据的封装、上报；
这样子，就完成了一个异常隔离机制：

* 它实现了：当SDK产生异常时不会影响主业务的流程；
* 当SDK产生异常时进行数据的封装、上报；
* 出现异常后，中止 SDK 的运行，并移除所有的监听；

## SDK 如何实现服务端时间的校对？

进行服务端时间的校对是什么意思。我们首先要明白，我们通过 JS 调用 new Date() 获取的时间，是我们的机器时间；也就是说：这个时间是一个随时都有可能不准确的时间。那么既然时间是不准确的，假如有一个对时间精准度要求比较敏感的功能：比如说 API全链路监控；最后整体绘制出来的全链路图直接客户端的访问时间点变成了未来的时间点，直接时间穿梭那可不行。

我们先要了解的是，http响应头 上有一个字段 Date。它的值是服务端发送资源时的服务器时间，我们可以在初始化SDK的时候，发送一个简单的请求给上报服务器，获取返回的 Date 值后计算 Diff差值 存在本地。

这样子就可以提供一个 公共API，来提供一个时间校对的服务，让本地的时间 比较趋近于 服务端的真实时间；（只是比较趋近的原因是：还会有一个单程传输耗时的误差）
```
let diff = 0;
export const diffTime = (date: string) => {
  const serverDate = new Date(date);
  const inDiff = Date.now() - serverDate.getTime();
  if (diff === 0 || diff > inDiff) {
    diff = inDiff;
  }
};

export const getTime = () => {
  return new Date(Date.now() - diff);
};
```
当然，这里还可以做的更精确一点，我们可以让后端服务在返回的时候，带上 API 请求在后端服务执行完毕所消耗的时间 server-timing，放在响应头里；我们取到数据后，将 ttfb 耗时 减去返回的 server-timing 再除以 2；就是单程传输的耗时；那这样我们上文的计算中差的 单程传输耗时的误差 就可以补上了。

## SDK 如何实现会话级别的错误上报去重？

首先，我们需要理清一个概念，我们可以认为：

在用户的一次会话中，如果产生了同一个错误，那么将这同一个错误上报多次是没有意义的。
在用户的不同会话中，如果产生了同一个错误，那么将不同会话中产生的错误进行上报是有意义的。

错误 mid 的操作，这是一个唯一id，但是它的唯一规则是针对于不同错误的唯一。

所以说我们传入的参数，是 错误信息、错误行号、错误列号、错误文件等可能的关键信息的一个集合，这样保证了产生在同一个地方的错误，生成的 错误 mid 都是相等的；这样子，我们才能在错误上报的入口函数里，做上报去重。

## SDK 如何生成错误唯一 ID

上面我们有提到一个 错误ID，它的作用分两种：

在客户端用以实现会话级别的上报去重。
在服务端用以实现相同错误的数据聚合。

但在实际应用中，我们如果仅仅根据 错误信息、错误行号、错误列号、错误文件 来进行判断，可能还不够准确，所以，我们需要将堆栈信息纳入聚合算法中。我们根据错误堆栈，解析出了 错误文件名、错误函数名、错误行号、错误列号等信息。

我们再利用上述的所有信息，最终生成一个 hash值，这个值就是能够完全的描述这个错误的唯一性的 ID。

## SDK 采用什么样的上报策略

SDK的数据上报可不是随随便便就上报上去了，里面有涉及到数据上报的方式取舍以及上报时机的选择等等，还有一些可以让数据上报更加优雅的优化点。日志上报行为不应该影响业务逻辑，不应该占用业务计算资源。

[Beacon API](https://developer.mozilla.org/zh-CN/docs/Web/API/Beacon_API)

* 它可以将数据以 POST 方法将少量数据发送到服务端
* 它保证页面卸载之前启动信标请求
* 并允许运行完成且不会阻塞请求或阻塞处理用户交互事件的任务。

然后 Ajax 请求方式就不用我多说了，大家应该平常用的最多的异步请求就是 Ajax。

最后来说一下 Image 上报方式：我们可以以向服务端请求图片资源的形式，像服务端传输少量数据，这种方式不会造成跨域。


## 上报方式

看了上面的三种上报方式，我们最终采用 sendBeacon + xmlHttpRequest 降级上报的方式，当浏览器不支持 sendBeacon 或者 传输的数据量超过了 sendBeacon 的限制，我们就降级采用 xmlHttpRequest 进行上报数据；
优先选用 Beacon API 的理由上文已经有提到：它可以保证页面卸载之前启动信标请求，是一种数据可靠，传输异步并且不会影响下一页面的加载 的传输方式。

而降级使用 XMLHttpRequest 的原因是， Beacon API 现在并不是所有的浏览器都完全支持，我们需要一个保险方案兜底，并且 sendbeacon 不能传输大数据量的信息，这个时候还是得回到 Ajax 来。

看到了这里，有的同学可能会问：为什么不用 Image 呀？那跨域怎么办呀？原因也很简单：

Image 是以GET方式请求图片资源的方式，将上报数据附在 URL 上携带到服务端，而URL地址的长度是有一定限制的。规范对 URL 长度并没有要求，但是浏览器、服务器、代理服务器都对 URL 长度有要求。有的浏览器要求URL中path部分不超过 2048，这就导致有些请求会发送不完全。
至于跨域问题，作为接受数据上报的服务端，允许跨域是理所应当的

上报时机这里，一般来说：

* PV、错误、用户自定义行为 都是触发后立即就进行上报；
* 性能数据 需要等待页面加载完成、数据采集完毕后进行上报；
* API请求数据 会进行本地暂存，在数据量达到10条(自拟)时触发一次上报，并且在页面可见性变化、以及页面关闭之前进行上报；
* 如果你还要上报 点击行为 等其余的数据，跟 API请求数据 一样的上报时机；

## 上报优化
或许，我们想把我们的数据上报做的再优雅一点，那么我们还有什么可以优化的点呢？还是有的：

启用 HTTP2，在 HTTP1 中，每次日志上报请求头都携带了大量的重复数据导致性能浪费。HTTP2头部压缩 采用Huffman Code压缩请求头，能有效减少请求头的大小；
服务端可以返回 204 状态码，省去响应体；
使用 requestIdleCallback ，这是一个较新的 API，它可以插入一个函数，这个函数将在浏览器空闲时期被调用。这使开发者能够在主事件循环上执行后台和低优先级工作，而不会影响延迟关键事件，如果不支持的话，就使用 settimeout；

## 平台数据如何进行 削峰限流

### 简单方案-随机丢弃策略进行限流

前端做削峰限流最简单的方法是什么？没错，就是 Math.random() ，我们让用户传入一个采样率，
if(Math.random()<0.5) return;

非常简单的就实现了！但是这个方案不是一个很优雅的解决办法，为什么呢？

大流量项目限制了 50% 的流量，它的流量仍然多；
小流量项目限制了 50% 的流量，那就没有流量了；

### 优化方案-流量整型

计数器算法：计数器算法就是单位时间内入库数量固定，后面的数据全部丢弃；缺点是无法应对恶意用户；

漏桶算法：漏桶算法就是系统以固有的速率处理请求，当请求太多超过了桶的容量时，请求就会被丢弃；缺点是漏桶算法对于骤增的流量来说缺乏效率；

令牌桶算法：令牌桶算法就是系统会以恒定的速度往固定容量的桶里放入令牌，当请求需要被处理时就会从桶里取一个令牌，当没有令牌可取的时候就会据拒绝服务；

计数器能够削峰，限制最大并发数以保证服务高可用
令牌桶实现流量均匀入库，保证下游服务健康
最终选择了 计数器 + 令牌桶 的方案

首先从外部来的流量是我们无法预估的，假设如上图我们有三个 服务器Pod ，如果总流量来的非常大，那么这时我们通过计数器算法，给它设置一个很大的最大值；这个最大值只防小人不防君子，可能 99% 的项目都不会触发。

这样经过总流量的计数器削峰后，再到中心化的令牌桶限流：通过 redis 来实现，我们先做一个定时器每分钟都去令牌桶里写令牌，然后单机的流量每个进来后，都去 redis 里取令牌，有令牌就处理入库；没有令牌就把流量抛弃。

这样子我们就实现了一个 单机的削峰 + 中心化的限流，两者一结合，就是解决了小流量应用限流后没流量的问题，以及控制了入库的数量均匀且稳定。

## 平台数据为什么需要 数据加工

为什么需要数据加工，以及数据加工需要做什么处理？

当我们的数据上报之后，因为 IP地址 是在服务端获取的嘛，所以服务端就需要有一个服务，去统一给请求数据中家加上 IP地址 以及 IP地址 解析后的归属地、运营商等信息。

根据业务需要，还可以加上服务端服务的版本号 等其余信息，方便后续做追踪；

## 平台数据为什么需要 数据清洗、聚合

数据清洗是为了白名单、黑名单过滤等的业务需要，还有避免已关闭的应用数据继续入库；
数据聚合是为了将相同信息的数据进行抽象聚合成 issue，以便查询和追踪；

这样子假设后续我们需要在数据库查询：某一条错误，产生了几次，影响了几个人，错误率是多少，这样子可以不用再去 ES 中捞日志，而是在 MySQL 中直接查询即可；
并且，我们还可以将抽象聚合出来的 issue ，关联于公司的 缺陷平台（类bug管理平台） ，实现 issue追踪 、 直接自动贴bug到负责人头上 等业务功能；




